2022-10-06 18:38:56,129 - apscheduler.scheduler - INFO - Scheduler started
2022-10-06 18:38:59,867 - telegram.ext.dispatcher - ERROR - No error handlers are registered, logging exception.
Traceback (most recent call last):
  File "/home/yusifmorley/Project/PycharmProject/TelegramBot/venv/lib/python3.10/site-packages/telegram/ext/dispatcher.py", line 555, in process_update
    handler.handle_update(update, self, check, context)
  File "/home/yusifmorley/Project/PycharmProject/TelegramBot/venv/lib/python3.10/site-packages/telegram/ext/handler.py", line 198, in handle_update
    return self.callback(update, context)
  File "/home/yusifmorley/Project/PycharmProject/TelegramBot/main2.py", line 96, in adminhanderex
    context.bot.delete_message(chat_id=update.effective_chat.id, message_id=update.effective_message.message_id)
  File "/home/yusifmorley/Project/PycharmProject/TelegramBot/venv/lib/python3.10/site-packages/telegram/bot.py", line 130, in decorator
    result = func(*args, **kwargs)
  File "/home/yusifmorley/Project/PycharmProject/TelegramBot/venv/lib/python3.10/site-packages/telegram/bot.py", line 576, in delete_message
    result = self._post('deleteMessage', data, timeout=timeout, api_kwargs=api_kwargs)
  File "/home/yusifmorley/Project/PycharmProject/TelegramBot/venv/lib/python3.10/site-packages/telegram/bot.py", line 295, in _post
    return self.request.post(
  File "/home/yusifmorley/Project/PycharmProject/TelegramBot/venv/lib/python3.10/site-packages/telegram/utils/request.py", line 361, in post
    result = self._request_wrapper(
  File "/home/yusifmorley/Project/PycharmProject/TelegramBot/venv/lib/python3.10/site-packages/telegram/utils/request.py", line 279, in _request_wrapper
    raise BadRequest(message)
telegram.error.BadRequest: Message to delete not found
2022-10-06 18:39:00,276 - telegram.ext.dispatcher - ERROR - No error handlers are registered, logging exception.
Traceback (most recent call last):
  File "/home/yusifmorley/Project/PycharmProject/TelegramBot/venv/lib/python3.10/site-packages/telegram/ext/dispatcher.py", line 555, in process_update
    handler.handle_update(update, self, check, context)
  File "/home/yusifmorley/Project/PycharmProject/TelegramBot/venv/lib/python3.10/site-packages/telegram/ext/handler.py", line 198, in handle_update
    return self.callback(update, context)
  File "/home/yusifmorley/Project/PycharmProject/TelegramBot/main2.py", line 96, in adminhanderex
    context.bot.delete_message(chat_id=update.effective_chat.id, message_id=update.effective_message.message_id)
  File "/home/yusifmorley/Project/PycharmProject/TelegramBot/venv/lib/python3.10/site-packages/telegram/bot.py", line 130, in decorator
    result = func(*args, **kwargs)
  File "/home/yusifmorley/Project/PycharmProject/TelegramBot/venv/lib/python3.10/site-packages/telegram/bot.py", line 576, in delete_message
    result = self._post('deleteMessage', data, timeout=timeout, api_kwargs=api_kwargs)
  File "/home/yusifmorley/Project/PycharmProject/TelegramBot/venv/lib/python3.10/site-packages/telegram/bot.py", line 295, in _post
    return self.request.post(
  File "/home/yusifmorley/Project/PycharmProject/TelegramBot/venv/lib/python3.10/site-packages/telegram/utils/request.py", line 361, in post
    result = self._request_wrapper(
  File "/home/yusifmorley/Project/PycharmProject/TelegramBot/venv/lib/python3.10/site-packages/telegram/utils/request.py", line 279, in _request_wrapper
    raise BadRequest(message)
telegram.error.BadRequest: Message to delete not found
2022-10-06 18:39:01,506 - telegram.ext.dispatcher - ERROR - No error handlers are registered, logging exception.
Traceback (most recent call last):
  File "/home/yusifmorley/Project/PycharmProject/TelegramBot/venv/lib/python3.10/site-packages/telegram/ext/dispatcher.py", line 555, in process_update
    handler.handle_update(update, self, check, context)
  File "/home/yusifmorley/Project/PycharmProject/TelegramBot/venv/lib/python3.10/site-packages/telegram/ext/handler.py", line 198, in handle_update
    return self.callback(update, context)
  File "/home/yusifmorley/Project/PycharmProject/TelegramBot/main2.py", line 96, in adminhanderex
    context.bot.delete_message(chat_id=update.effective_chat.id, message_id=update.effective_message.message_id)
  File "/home/yusifmorley/Project/PycharmProject/TelegramBot/venv/lib/python3.10/site-packages/telegram/bot.py", line 130, in decorator
    result = func(*args, **kwargs)
  File "/home/yusifmorley/Project/PycharmProject/TelegramBot/venv/lib/python3.10/site-packages/telegram/bot.py", line 576, in delete_message
    result = self._post('deleteMessage', data, timeout=timeout, api_kwargs=api_kwargs)
  File "/home/yusifmorley/Project/PycharmProject/TelegramBot/venv/lib/python3.10/site-packages/telegram/bot.py", line 295, in _post
    return self.request.post(
  File "/home/yusifmorley/Project/PycharmProject/TelegramBot/venv/lib/python3.10/site-packages/telegram/utils/request.py", line 361, in post
    result = self._request_wrapper(
  File "/home/yusifmorley/Project/PycharmProject/TelegramBot/venv/lib/python3.10/site-packages/telegram/utils/request.py", line 279, in _request_wrapper
    raise BadRequest(message)
telegram.error.BadRequest: Message to delete not found
2022-10-06 18:39:01,915 - telegram.ext.dispatcher - ERROR - No error handlers are registered, logging exception.
Traceback (most recent call last):
  File "/home/yusifmorley/Project/PycharmProject/TelegramBot/venv/lib/python3.10/site-packages/telegram/ext/dispatcher.py", line 555, in process_update
    handler.handle_update(update, self, check, context)
  File "/home/yusifmorley/Project/PycharmProject/TelegramBot/venv/lib/python3.10/site-packages/telegram/ext/handler.py", line 198, in handle_update
    return self.callback(update, context)
  File "/home/yusifmorley/Project/PycharmProject/TelegramBot/main2.py", line 96, in adminhanderex
    context.bot.delete_message(chat_id=update.effective_chat.id, message_id=update.effective_message.message_id)
  File "/home/yusifmorley/Project/PycharmProject/TelegramBot/venv/lib/python3.10/site-packages/telegram/bot.py", line 130, in decorator
    result = func(*args, **kwargs)
  File "/home/yusifmorley/Project/PycharmProject/TelegramBot/venv/lib/python3.10/site-packages/telegram/bot.py", line 576, in delete_message
    result = self._post('deleteMessage', data, timeout=timeout, api_kwargs=api_kwargs)
  File "/home/yusifmorley/Project/PycharmProject/TelegramBot/venv/lib/python3.10/site-packages/telegram/bot.py", line 295, in _post
    return self.request.post(
  File "/home/yusifmorley/Project/PycharmProject/TelegramBot/venv/lib/python3.10/site-packages/telegram/utils/request.py", line 361, in post
    result = self._request_wrapper(
  File "/home/yusifmorley/Project/PycharmProject/TelegramBot/venv/lib/python3.10/site-packages/telegram/utils/request.py", line 279, in _request_wrapper
    raise BadRequest(message)
telegram.error.BadRequest: Message to delete not found
2022-10-06 18:39:02,326 - telegram.ext.dispatcher - ERROR - No error handlers are registered, logging exception.
Traceback (most recent call last):
  File "/home/yusifmorley/Project/PycharmProject/TelegramBot/venv/lib/python3.10/site-packages/telegram/ext/dispatcher.py", line 555, in process_update
    handler.handle_update(update, self, check, context)
  File "/home/yusifmorley/Project/PycharmProject/TelegramBot/venv/lib/python3.10/site-packages/telegram/ext/handler.py", line 198, in handle_update
    return self.callback(update, context)
  File "/home/yusifmorley/Project/PycharmProject/TelegramBot/main2.py", line 96, in adminhanderex
    context.bot.delete_message(chat_id=update.effective_chat.id, message_id=update.effective_message.message_id)
  File "/home/yusifmorley/Project/PycharmProject/TelegramBot/venv/lib/python3.10/site-packages/telegram/bot.py", line 130, in decorator
    result = func(*args, **kwargs)
  File "/home/yusifmorley/Project/PycharmProject/TelegramBot/venv/lib/python3.10/site-packages/telegram/bot.py", line 576, in delete_message
    result = self._post('deleteMessage', data, timeout=timeout, api_kwargs=api_kwargs)
  File "/home/yusifmorley/Project/PycharmProject/TelegramBot/venv/lib/python3.10/site-packages/telegram/bot.py", line 295, in _post
    return self.request.post(
  File "/home/yusifmorley/Project/PycharmProject/TelegramBot/venv/lib/python3.10/site-packages/telegram/utils/request.py", line 361, in post
    result = self._request_wrapper(
  File "/home/yusifmorley/Project/PycharmProject/TelegramBot/venv/lib/python3.10/site-packages/telegram/utils/request.py", line 279, in _request_wrapper
    raise BadRequest(message)
telegram.error.BadRequest: Message to delete not found
2022-10-06 18:39:02,734 - telegram.ext.dispatcher - ERROR - No error handlers are registered, logging exception.
Traceback (most recent call last):
  File "/home/yusifmorley/Project/PycharmProject/TelegramBot/venv/lib/python3.10/site-packages/telegram/ext/dispatcher.py", line 555, in process_update
    handler.handle_update(update, self, check, context)
  File "/home/yusifmorley/Project/PycharmProject/TelegramBot/venv/lib/python3.10/site-packages/telegram/ext/handler.py", line 198, in handle_update
    return self.callback(update, context)
  File "/home/yusifmorley/Project/PycharmProject/TelegramBot/main2.py", line 96, in adminhanderex
    context.bot.delete_message(chat_id=update.effective_chat.id, message_id=update.effective_message.message_id)
  File "/home/yusifmorley/Project/PycharmProject/TelegramBot/venv/lib/python3.10/site-packages/telegram/bot.py", line 130, in decorator
    result = func(*args, **kwargs)
  File "/home/yusifmorley/Project/PycharmProject/TelegramBot/venv/lib/python3.10/site-packages/telegram/bot.py", line 576, in delete_message
    result = self._post('deleteMessage', data, timeout=timeout, api_kwargs=api_kwargs)
  File "/home/yusifmorley/Project/PycharmProject/TelegramBot/venv/lib/python3.10/site-packages/telegram/bot.py", line 295, in _post
    return self.request.post(
  File "/home/yusifmorley/Project/PycharmProject/TelegramBot/venv/lib/python3.10/site-packages/telegram/utils/request.py", line 361, in post
    result = self._request_wrapper(
  File "/home/yusifmorley/Project/PycharmProject/TelegramBot/venv/lib/python3.10/site-packages/telegram/utils/request.py", line 279, in _request_wrapper
    raise BadRequest(message)
telegram.error.BadRequest: Message to delete not found
2022-10-06 18:39:03,144 - telegram.ext.dispatcher - ERROR - No error handlers are registered, logging exception.
Traceback (most recent call last):
  File "/home/yusifmorley/Project/PycharmProject/TelegramBot/venv/lib/python3.10/site-packages/telegram/ext/dispatcher.py", line 555, in process_update
    handler.handle_update(update, self, check, context)
  File "/home/yusifmorley/Project/PycharmProject/TelegramBot/venv/lib/python3.10/site-packages/telegram/ext/handler.py", line 198, in handle_update
    return self.callback(update, context)
  File "/home/yusifmorley/Project/PycharmProject/TelegramBot/main2.py", line 96, in adminhanderex
    context.bot.delete_message(chat_id=update.effective_chat.id, message_id=update.effective_message.message_id)
  File "/home/yusifmorley/Project/PycharmProject/TelegramBot/venv/lib/python3.10/site-packages/telegram/bot.py", line 130, in decorator
    result = func(*args, **kwargs)
  File "/home/yusifmorley/Project/PycharmProject/TelegramBot/venv/lib/python3.10/site-packages/telegram/bot.py", line 576, in delete_message
    result = self._post('deleteMessage', data, timeout=timeout, api_kwargs=api_kwargs)
  File "/home/yusifmorley/Project/PycharmProject/TelegramBot/venv/lib/python3.10/site-packages/telegram/bot.py", line 295, in _post
    return self.request.post(
  File "/home/yusifmorley/Project/PycharmProject/TelegramBot/venv/lib/python3.10/site-packages/telegram/utils/request.py", line 361, in post
    result = self._request_wrapper(
  File "/home/yusifmorley/Project/PycharmProject/TelegramBot/venv/lib/python3.10/site-packages/telegram/utils/request.py", line 279, in _request_wrapper
    raise BadRequest(message)
telegram.error.BadRequest: Message to delete not found
2022-10-06 18:39:03,553 - telegram.ext.dispatcher - ERROR - No error handlers are registered, logging exception.
Traceback (most recent call last):
  File "/home/yusifmorley/Project/PycharmProject/TelegramBot/venv/lib/python3.10/site-packages/telegram/ext/dispatcher.py", line 555, in process_update
    handler.handle_update(update, self, check, context)
  File "/home/yusifmorley/Project/PycharmProject/TelegramBot/venv/lib/python3.10/site-packages/telegram/ext/handler.py", line 198, in handle_update
    return self.callback(update, context)
  File "/home/yusifmorley/Project/PycharmProject/TelegramBot/main2.py", line 96, in adminhanderex
    context.bot.delete_message(chat_id=update.effective_chat.id, message_id=update.effective_message.message_id)
  File "/home/yusifmorley/Project/PycharmProject/TelegramBot/venv/lib/python3.10/site-packages/telegram/bot.py", line 130, in decorator
    result = func(*args, **kwargs)
  File "/home/yusifmorley/Project/PycharmProject/TelegramBot/venv/lib/python3.10/site-packages/telegram/bot.py", line 576, in delete_message
    result = self._post('deleteMessage', data, timeout=timeout, api_kwargs=api_kwargs)
  File "/home/yusifmorley/Project/PycharmProject/TelegramBot/venv/lib/python3.10/site-packages/telegram/bot.py", line 295, in _post
    return self.request.post(
  File "/home/yusifmorley/Project/PycharmProject/TelegramBot/venv/lib/python3.10/site-packages/telegram/utils/request.py", line 361, in post
    result = self._request_wrapper(
  File "/home/yusifmorley/Project/PycharmProject/TelegramBot/venv/lib/python3.10/site-packages/telegram/utils/request.py", line 279, in _request_wrapper
    raise BadRequest(message)
telegram.error.BadRequest: Message to delete not found
2022-10-06 18:39:04,884 - telegram.ext.dispatcher - ERROR - No error handlers are registered, logging exception.
Traceback (most recent call last):
  File "/home/yusifmorley/Project/PycharmProject/TelegramBot/venv/lib/python3.10/site-packages/telegram/ext/dispatcher.py", line 555, in process_update
    handler.handle_update(update, self, check, context)
  File "/home/yusifmorley/Project/PycharmProject/TelegramBot/venv/lib/python3.10/site-packages/telegram/ext/handler.py", line 198, in handle_update
    return self.callback(update, context)
  File "/home/yusifmorley/Project/PycharmProject/TelegramBot/main2.py", line 116, in adminhanderex
    mysqlop.getbanwords(mydb,update.effective_chat.id)+os
  File "/home/yusifmorley/Project/PycharmProject/TelegramBot/mysqlop.py", line 114, in getbanwords
    return mycursor.fetchone[0]
TypeError: 'method' object is not subscriptable
2022-10-06 18:39:05,499 - telegram.ext.dispatcher - ERROR - No error handlers are registered, logging exception.
Traceback (most recent call last):
  File "/home/yusifmorley/Project/PycharmProject/TelegramBot/venv/lib/python3.10/site-packages/telegram/ext/dispatcher.py", line 555, in process_update
    handler.handle_update(update, self, check, context)
  File "/home/yusifmorley/Project/PycharmProject/TelegramBot/venv/lib/python3.10/site-packages/telegram/ext/handler.py", line 198, in handle_update
    return self.callback(update, context)
  File "/home/yusifmorley/Project/PycharmProject/TelegramBot/main2.py", line 98, in adminhanderex
    num= mysqlop.getbannum(mydb, update.effective_chat.id)
  File "/home/yusifmorley/Project/PycharmProject/TelegramBot/mysqlop.py", line 92, in getbannum
    mycursor = mydb.cursor()
  File "/home/yusifmorley/Project/PycharmProject/TelegramBot/venv/lib/python3.10/site-packages/mysql/connector/connection_cext.py", line 588, in cursor
    self.handle_unread_result(prepared)
  File "/home/yusifmorley/Project/PycharmProject/TelegramBot/venv/lib/python3.10/site-packages/mysql/connector/connection_cext.py", line 803, in handle_unread_result
    raise errors.InternalError("Unread result found")
mysql.connector.errors.InternalError: Unread result found
2022-10-06 18:56:49,547 - apscheduler.scheduler - INFO - Scheduler started
2022-10-06 19:01:59,866 - telegram.ext.dispatcher - ERROR - No error handlers are registered, logging exception.
Traceback (most recent call last):
  File "/home/yusifmorley/Project/PycharmProject/TelegramBot/venv/lib/python3.10/site-packages/telegram/ext/dispatcher.py", line 555, in process_update
    handler.handle_update(update, self, check, context)
  File "/home/yusifmorley/Project/PycharmProject/TelegramBot/venv/lib/python3.10/site-packages/telegram/ext/handler.py", line 198, in handle_update
    return self.callback(update, context)
  File "/home/yusifmorley/Project/PycharmProject/TelegramBot/main2.py", line 120, in adminhanderex
    mysqlop.getbanwords(mydb,update.effective_chat.id)+os
  File "/home/yusifmorley/Project/PycharmProject/TelegramBot/mysqlop.py", line 114, in getbanwords
    return mycursor.fetchone[0]
TypeError: 'method' object is not subscriptable
2022-10-06 19:06:35,683 - apscheduler.scheduler - INFO - Scheduler started
2022-10-06 19:06:45,258 - telegram.ext.dispatcher - ERROR - No error handlers are registered, logging exception.
Traceback (most recent call last):
  File "/home/yusifmorley/Project/PycharmProject/TelegramBot/venv/lib/python3.10/site-packages/telegram/ext/dispatcher.py", line 555, in process_update
    handler.handle_update(update, self, check, context)
  File "/home/yusifmorley/Project/PycharmProject/TelegramBot/venv/lib/python3.10/site-packages/telegram/ext/handler.py", line 198, in handle_update
    return self.callback(update, context)
  File "/home/yusifmorley/Project/PycharmProject/TelegramBot/main2.py", line 121, in adminhanderex
    mysqlop.getbanwords(mydb,update.effective_chat.id)+os
  File "/home/yusifmorley/Project/PycharmProject/TelegramBot/mysqlop.py", line 114, in getbanwords
    return mycursor.fetchone[0]
TypeError: 'method' object is not subscriptable
2022-10-06 19:06:48,710 - apscheduler.scheduler - INFO - Scheduler started
2022-10-06 19:07:22,339 - telegram.ext.dispatcher - ERROR - No error handlers are registered, logging exception.
Traceback (most recent call last):
  File "/home/yusifmorley/Project/PycharmProject/TelegramBot/venv/lib/python3.10/site-packages/telegram/ext/dispatcher.py", line 555, in process_update
    handler.handle_update(update, self, check, context)
  File "/home/yusifmorley/Project/PycharmProject/TelegramBot/venv/lib/python3.10/site-packages/telegram/ext/handler.py", line 198, in handle_update
    return self.callback(update, context)
  File "/home/yusifmorley/Project/PycharmProject/TelegramBot/main2.py", line 121, in adminhanderex
    mysqlop.getbanwords(mydb,update.effective_chat.id)+os
  File "/home/yusifmorley/Project/PycharmProject/TelegramBot/mysqlop.py", line 114, in getbanwords
    return mycursor.fetchone[0]
TypeError: 'method' object is not subscriptable
2022-10-06 19:12:57,716 - apscheduler.scheduler - INFO - Scheduler started
2022-10-06 19:13:01,278 - telegram.ext.dispatcher - ERROR - No error handlers are registered, logging exception.
Traceback (most recent call last):
  File "/home/yusifmorley/Project/PycharmProject/TelegramBot/venv/lib/python3.10/site-packages/telegram/ext/dispatcher.py", line 555, in process_update
    handler.handle_update(update, self, check, context)
  File "/home/yusifmorley/Project/PycharmProject/TelegramBot/venv/lib/python3.10/site-packages/telegram/ext/handler.py", line 198, in handle_update
    return self.callback(update, context)
  File "/home/yusifmorley/Project/PycharmProject/TelegramBot/main2.py", line 96, in adminhanderex
    context.bot.delete_message(chat_id=update.effective_chat.id, message_id=update.effective_message.message_id)
  File "/home/yusifmorley/Project/PycharmProject/TelegramBot/venv/lib/python3.10/site-packages/telegram/bot.py", line 130, in decorator
    result = func(*args, **kwargs)
  File "/home/yusifmorley/Project/PycharmProject/TelegramBot/venv/lib/python3.10/site-packages/telegram/bot.py", line 576, in delete_message
    result = self._post('deleteMessage', data, timeout=timeout, api_kwargs=api_kwargs)
  File "/home/yusifmorley/Project/PycharmProject/TelegramBot/venv/lib/python3.10/site-packages/telegram/bot.py", line 295, in _post
    return self.request.post(
  File "/home/yusifmorley/Project/PycharmProject/TelegramBot/venv/lib/python3.10/site-packages/telegram/utils/request.py", line 361, in post
    result = self._request_wrapper(
  File "/home/yusifmorley/Project/PycharmProject/TelegramBot/venv/lib/python3.10/site-packages/telegram/utils/request.py", line 279, in _request_wrapper
    raise BadRequest(message)
telegram.error.BadRequest: Message to delete not found
2022-10-06 19:13:04,865 - telegram.ext.dispatcher - ERROR - No error handlers are registered, logging exception.
Traceback (most recent call last):
  File "/home/yusifmorley/Project/PycharmProject/TelegramBot/venv/lib/python3.10/site-packages/mysql/connector/connection_cext.py", line 535, in cmd_query
    self._cmysql.query(query,
_mysql_connector.MySQLInterfaceError: Duplicate entry '-1001313322278' for key 'bans.PRIMARY'

During handling of the above exception, another exception occurred:

Traceback (most recent call last):
  File "/home/yusifmorley/Project/PycharmProject/TelegramBot/venv/lib/python3.10/site-packages/telegram/ext/dispatcher.py", line 555, in process_update
    handler.handle_update(update, self, check, context)
  File "/home/yusifmorley/Project/PycharmProject/TelegramBot/venv/lib/python3.10/site-packages/telegram/ext/handler.py", line 198, in handle_update
    return self.callback(update, context)
  File "/home/yusifmorley/Project/PycharmProject/TelegramBot/main2.py", line 101, in adminhanderex
    mysqlop.creatbanuser(mydb,update.effective_chat.id,os)
  File "/home/yusifmorley/Project/PycharmProject/TelegramBot/mysqlop.py", line 108, in creatbanuser
    mycursor.execute("insert into bans (uid, banword) values({},'{}')".format(id,banword))
  File "/home/yusifmorley/Project/PycharmProject/TelegramBot/venv/lib/python3.10/site-packages/mysql/connector/cursor_cext.py", line 269, in execute
    result = self._cnx.cmd_query(stmt, raw=self._raw,
  File "/home/yusifmorley/Project/PycharmProject/TelegramBot/venv/lib/python3.10/site-packages/mysql/connector/connection_cext.py", line 540, in cmd_query
    raise errors.get_mysql_exception(exc.errno, msg=exc.msg,
mysql.connector.errors.IntegrityError: 1062 (23000): Duplicate entry '-1001313322278' for key 'bans.PRIMARY'
2022-10-06 19:13:08,653 - telegram.ext.dispatcher - ERROR - No error handlers are registered, logging exception.
Traceback (most recent call last):
  File "/home/yusifmorley/Project/PycharmProject/TelegramBot/venv/lib/python3.10/site-packages/mysql/connector/connection_cext.py", line 535, in cmd_query
    self._cmysql.query(query,
_mysql_connector.MySQLInterfaceError: Duplicate entry '-1001313322278' for key 'bans.PRIMARY'

During handling of the above exception, another exception occurred:

Traceback (most recent call last):
  File "/home/yusifmorley/Project/PycharmProject/TelegramBot/venv/lib/python3.10/site-packages/telegram/ext/dispatcher.py", line 555, in process_update
    handler.handle_update(update, self, check, context)
  File "/home/yusifmorley/Project/PycharmProject/TelegramBot/venv/lib/python3.10/site-packages/telegram/ext/handler.py", line 198, in handle_update
    return self.callback(update, context)
  File "/home/yusifmorley/Project/PycharmProject/TelegramBot/main2.py", line 101, in adminhanderex
    mysqlop.creatbanuser(mydb,update.effective_chat.id,os)
  File "/home/yusifmorley/Project/PycharmProject/TelegramBot/mysqlop.py", line 108, in creatbanuser
    mycursor.execute("insert into bans (uid, banword) values({},'{}')".format(id,banword))
  File "/home/yusifmorley/Project/PycharmProject/TelegramBot/venv/lib/python3.10/site-packages/mysql/connector/cursor_cext.py", line 269, in execute
    result = self._cnx.cmd_query(stmt, raw=self._raw,
  File "/home/yusifmorley/Project/PycharmProject/TelegramBot/venv/lib/python3.10/site-packages/mysql/connector/connection_cext.py", line 540, in cmd_query
    raise errors.get_mysql_exception(exc.errno, msg=exc.msg,
mysql.connector.errors.IntegrityError: 1062 (23000): Duplicate entry '-1001313322278' for key 'bans.PRIMARY'
2022-10-06 19:13:12,442 - telegram.ext.dispatcher - ERROR - No error handlers are registered, logging exception.
Traceback (most recent call last):
  File "/home/yusifmorley/Project/PycharmProject/TelegramBot/venv/lib/python3.10/site-packages/mysql/connector/connection_cext.py", line 535, in cmd_query
    self._cmysql.query(query,
_mysql_connector.MySQLInterfaceError: Duplicate entry '-1001313322278' for key 'bans.PRIMARY'

During handling of the above exception, another exception occurred:

Traceback (most recent call last):
  File "/home/yusifmorley/Project/PycharmProject/TelegramBot/venv/lib/python3.10/site-packages/telegram/ext/dispatcher.py", line 555, in process_update
    handler.handle_update(update, self, check, context)
  File "/home/yusifmorley/Project/PycharmProject/TelegramBot/venv/lib/python3.10/site-packages/telegram/ext/handler.py", line 198, in handle_update
    return self.callback(update, context)
  File "/home/yusifmorley/Project/PycharmProject/TelegramBot/main2.py", line 101, in adminhanderex
    mysqlop.creatbanuser(mydb,update.effective_chat.id,os)
  File "/home/yusifmorley/Project/PycharmProject/TelegramBot/mysqlop.py", line 108, in creatbanuser
    mycursor.execute("insert into bans (uid, banword) values({},'{}')".format(id,banword))
  File "/home/yusifmorley/Project/PycharmProject/TelegramBot/venv/lib/python3.10/site-packages/mysql/connector/cursor_cext.py", line 269, in execute
    result = self._cnx.cmd_query(stmt, raw=self._raw,
  File "/home/yusifmorley/Project/PycharmProject/TelegramBot/venv/lib/python3.10/site-packages/mysql/connector/connection_cext.py", line 540, in cmd_query
    raise errors.get_mysql_exception(exc.errno, msg=exc.msg,
mysql.connector.errors.IntegrityError: 1062 (23000): Duplicate entry '-1001313322278' for key 'bans.PRIMARY'
2022-10-06 19:13:16,539 - telegram.ext.dispatcher - ERROR - No error handlers are registered, logging exception.
Traceback (most recent call last):
  File "/home/yusifmorley/Project/PycharmProject/TelegramBot/venv/lib/python3.10/site-packages/mysql/connector/connection_cext.py", line 535, in cmd_query
    self._cmysql.query(query,
_mysql_connector.MySQLInterfaceError: Duplicate entry '-1001313322278' for key 'bans.PRIMARY'

During handling of the above exception, another exception occurred:

Traceback (most recent call last):
  File "/home/yusifmorley/Project/PycharmProject/TelegramBot/venv/lib/python3.10/site-packages/telegram/ext/dispatcher.py", line 555, in process_update
    handler.handle_update(update, self, check, context)
  File "/home/yusifmorley/Project/PycharmProject/TelegramBot/venv/lib/python3.10/site-packages/telegram/ext/handler.py", line 198, in handle_update
    return self.callback(update, context)
  File "/home/yusifmorley/Project/PycharmProject/TelegramBot/main2.py", line 101, in adminhanderex
    mysqlop.creatbanuser(mydb,update.effective_chat.id,os)
  File "/home/yusifmorley/Project/PycharmProject/TelegramBot/mysqlop.py", line 108, in creatbanuser
    mycursor.execute("insert into bans (uid, banword) values({},'{}')".format(id,banword))
  File "/home/yusifmorley/Project/PycharmProject/TelegramBot/venv/lib/python3.10/site-packages/mysql/connector/cursor_cext.py", line 269, in execute
    result = self._cnx.cmd_query(stmt, raw=self._raw,
  File "/home/yusifmorley/Project/PycharmProject/TelegramBot/venv/lib/python3.10/site-packages/mysql/connector/connection_cext.py", line 540, in cmd_query
    raise errors.get_mysql_exception(exc.errno, msg=exc.msg,
mysql.connector.errors.IntegrityError: 1062 (23000): Duplicate entry '-1001313322278' for key 'bans.PRIMARY'
2022-10-06 19:13:20,837 - telegram.ext.dispatcher - ERROR - No error handlers are registered, logging exception.
Traceback (most recent call last):
  File "/home/yusifmorley/Project/PycharmProject/TelegramBot/venv/lib/python3.10/site-packages/mysql/connector/connection_cext.py", line 535, in cmd_query
    self._cmysql.query(query,
_mysql_connector.MySQLInterfaceError: Duplicate entry '-1001313322278' for key 'bans.PRIMARY'

During handling of the above exception, another exception occurred:

Traceback (most recent call last):
  File "/home/yusifmorley/Project/PycharmProject/TelegramBot/venv/lib/python3.10/site-packages/telegram/ext/dispatcher.py", line 555, in process_update
    handler.handle_update(update, self, check, context)
  File "/home/yusifmorley/Project/PycharmProject/TelegramBot/venv/lib/python3.10/site-packages/telegram/ext/handler.py", line 198, in handle_update
    return self.callback(update, context)
  File "/home/yusifmorley/Project/PycharmProject/TelegramBot/main2.py", line 101, in adminhanderex
    mysqlop.creatbanuser(mydb,update.effective_chat.id,os)
  File "/home/yusifmorley/Project/PycharmProject/TelegramBot/mysqlop.py", line 108, in creatbanuser
    mycursor.execute("insert into bans (uid, banword) values({},'{}')".format(id,banword))
  File "/home/yusifmorley/Project/PycharmProject/TelegramBot/venv/lib/python3.10/site-packages/mysql/connector/cursor_cext.py", line 269, in execute
    result = self._cnx.cmd_query(stmt, raw=self._raw,
  File "/home/yusifmorley/Project/PycharmProject/TelegramBot/venv/lib/python3.10/site-packages/mysql/connector/connection_cext.py", line 540, in cmd_query
    raise errors.get_mysql_exception(exc.errno, msg=exc.msg,
mysql.connector.errors.IntegrityError: 1062 (23000): Duplicate entry '-1001313322278' for key 'bans.PRIMARY'
2022-10-06 19:13:27,421 - apscheduler.scheduler - INFO - Scheduler started
2022-10-06 19:13:36,197 - telegram.ext.dispatcher - ERROR - No error handlers are registered, logging exception.
Traceback (most recent call last):
  File "/home/yusifmorley/Project/PycharmProject/TelegramBot/venv/lib/python3.10/site-packages/mysql/connector/connection_cext.py", line 535, in cmd_query
    self._cmysql.query(query,
_mysql_connector.MySQLInterfaceError: Duplicate entry '-1001313322278' for key 'bans.PRIMARY'

During handling of the above exception, another exception occurred:

Traceback (most recent call last):
  File "/home/yusifmorley/Project/PycharmProject/TelegramBot/venv/lib/python3.10/site-packages/telegram/ext/dispatcher.py", line 555, in process_update
    handler.handle_update(update, self, check, context)
  File "/home/yusifmorley/Project/PycharmProject/TelegramBot/venv/lib/python3.10/site-packages/telegram/ext/handler.py", line 198, in handle_update
    return self.callback(update, context)
  File "/home/yusifmorley/Project/PycharmProject/TelegramBot/main2.py", line 101, in adminhanderex
    mysqlop.creatbanuser(mydb,update.effective_chat.id,os)
  File "/home/yusifmorley/Project/PycharmProject/TelegramBot/mysqlop.py", line 108, in creatbanuser
    mycursor.execute("insert into bans (uid, banword) values({},'{}')".format(id,banword))
  File "/home/yusifmorley/Project/PycharmProject/TelegramBot/venv/lib/python3.10/site-packages/mysql/connector/cursor_cext.py", line 269, in execute
    result = self._cnx.cmd_query(stmt, raw=self._raw,
  File "/home/yusifmorley/Project/PycharmProject/TelegramBot/venv/lib/python3.10/site-packages/mysql/connector/connection_cext.py", line 540, in cmd_query
    raise errors.get_mysql_exception(exc.errno, msg=exc.msg,
mysql.connector.errors.IntegrityError: 1062 (23000): Duplicate entry '-1001313322278' for key 'bans.PRIMARY'
2022-10-06 19:14:11,731 - telegram.ext.dispatcher - ERROR - No error handlers are registered, logging exception.
Traceback (most recent call last):
  File "/home/yusifmorley/Project/PycharmProject/TelegramBot/venv/lib/python3.10/site-packages/mysql/connector/connection_cext.py", line 535, in cmd_query
    self._cmysql.query(query,
_mysql_connector.MySQLInterfaceError: Duplicate entry '-1001313322278' for key 'bans.PRIMARY'

During handling of the above exception, another exception occurred:

Traceback (most recent call last):
  File "/home/yusifmorley/Project/PycharmProject/TelegramBot/venv/lib/python3.10/site-packages/telegram/ext/dispatcher.py", line 555, in process_update
    handler.handle_update(update, self, check, context)
  File "/home/yusifmorley/Project/PycharmProject/TelegramBot/venv/lib/python3.10/site-packages/telegram/ext/handler.py", line 198, in handle_update
    return self.callback(update, context)
  File "/home/yusifmorley/Project/PycharmProject/TelegramBot/main2.py", line 101, in adminhanderex
    mysqlop.creatbanuser(mydb,update.effective_chat.id,os)
  File "/home/yusifmorley/Project/PycharmProject/TelegramBot/mysqlop.py", line 108, in creatbanuser
    mycursor.execute("insert into bans (uid, banword) values({},'{}')".format(id,banword))
  File "/home/yusifmorley/Project/PycharmProject/TelegramBot/venv/lib/python3.10/site-packages/mysql/connector/cursor_cext.py", line 269, in execute
    result = self._cnx.cmd_query(stmt, raw=self._raw,
  File "/home/yusifmorley/Project/PycharmProject/TelegramBot/venv/lib/python3.10/site-packages/mysql/connector/connection_cext.py", line 540, in cmd_query
    raise errors.get_mysql_exception(exc.errno, msg=exc.msg,
mysql.connector.errors.IntegrityError: 1062 (23000): Duplicate entry '-1001313322278' for key 'bans.PRIMARY'
2022-10-06 19:14:14,707 - apscheduler.scheduler - INFO - Scheduler started
2022-10-06 19:14:20,307 - apscheduler.scheduler - INFO - Scheduler started
2022-10-06 19:14:27,807 - telegram.ext.dispatcher - ERROR - No error handlers are registered, logging exception.
Traceback (most recent call last):
  File "/home/yusifmorley/Project/PycharmProject/TelegramBot/venv/lib/python3.10/site-packages/mysql/connector/connection_cext.py", line 535, in cmd_query
    self._cmysql.query(query,
_mysql_connector.MySQLInterfaceError: Duplicate entry '-1001313322278' for key 'bans.PRIMARY'

During handling of the above exception, another exception occurred:

Traceback (most recent call last):
  File "/home/yusifmorley/Project/PycharmProject/TelegramBot/venv/lib/python3.10/site-packages/telegram/ext/dispatcher.py", line 555, in process_update
    handler.handle_update(update, self, check, context)
  File "/home/yusifmorley/Project/PycharmProject/TelegramBot/venv/lib/python3.10/site-packages/telegram/ext/handler.py", line 198, in handle_update
    return self.callback(update, context)
  File "/home/yusifmorley/Project/PycharmProject/TelegramBot/main2.py", line 101, in adminhanderex
    mysqlop.creatbanuser(mydb,update.effective_chat.id,os)
  File "/home/yusifmorley/Project/PycharmProject/TelegramBot/mysqlop.py", line 108, in creatbanuser
    mycursor.execute("insert into bans (uid, banword) values({},'{}')".format(id,banword))
  File "/home/yusifmorley/Project/PycharmProject/TelegramBot/venv/lib/python3.10/site-packages/mysql/connector/cursor_cext.py", line 269, in execute
    result = self._cnx.cmd_query(stmt, raw=self._raw,
  File "/home/yusifmorley/Project/PycharmProject/TelegramBot/venv/lib/python3.10/site-packages/mysql/connector/connection_cext.py", line 540, in cmd_query
    raise errors.get_mysql_exception(exc.errno, msg=exc.msg,
mysql.connector.errors.IntegrityError: 1062 (23000): Duplicate entry '-1001313322278' for key 'bans.PRIMARY'
2022-10-06 19:14:51,920 - apscheduler.scheduler - INFO - Scheduler started
2022-10-06 19:15:14,600 - telegram.ext.dispatcher - ERROR - No error handlers are registered, logging exception.
Traceback (most recent call last):
  File "/home/yusifmorley/Project/PycharmProject/TelegramBot/venv/lib/python3.10/site-packages/mysql/connector/connection_cext.py", line 535, in cmd_query
    self._cmysql.query(query,
_mysql_connector.MySQLInterfaceError: Duplicate entry '-1001313322278' for key 'bans.PRIMARY'

During handling of the above exception, another exception occurred:

Traceback (most recent call last):
  File "/home/yusifmorley/Project/PycharmProject/TelegramBot/venv/lib/python3.10/site-packages/telegram/ext/dispatcher.py", line 555, in process_update
    handler.handle_update(update, self, check, context)
  File "/home/yusifmorley/Project/PycharmProject/TelegramBot/venv/lib/python3.10/site-packages/telegram/ext/handler.py", line 198, in handle_update
    return self.callback(update, context)
  File "/home/yusifmorley/Project/PycharmProject/TelegramBot/main2.py", line 101, in adminhanderex
    mysqlop.creatbanuser(mydb,update.effective_chat.id,os)
  File "/home/yusifmorley/Project/PycharmProject/TelegramBot/mysqlop.py", line 108, in creatbanuser
    mycursor.execute("insert into bans (uid, banword) values({},'{}')".format(id,banword))
  File "/home/yusifmorley/Project/PycharmProject/TelegramBot/venv/lib/python3.10/site-packages/mysql/connector/cursor_cext.py", line 269, in execute
    result = self._cnx.cmd_query(stmt, raw=self._raw,
  File "/home/yusifmorley/Project/PycharmProject/TelegramBot/venv/lib/python3.10/site-packages/mysql/connector/connection_cext.py", line 540, in cmd_query
    raise errors.get_mysql_exception(exc.errno, msg=exc.msg,
mysql.connector.errors.IntegrityError: 1062 (23000): Duplicate entry '-1001313322278' for key 'bans.PRIMARY'
2022-10-06 19:16:09,281 - apscheduler.scheduler - INFO - Scheduler started
2022-10-06 19:21:16,742 - apscheduler.scheduler - INFO - Scheduler started
2022-10-06 19:21:35,074 - telegram.vendor.ptb_urllib3.urllib3.connectionpool - WARNING - Retrying (Retry(total=2, connect=None, read=None, redirect=None)) after connection broken by 'ConnectTimeoutError(<telegram.vendor.ptb_urllib3.urllib3.connectionpool.HTTPSConnectionPool object at 0x7ff3a8124550>, 'Connect timed out. (connect timeout=5.0)')': /bot5738858657:AAFJmjtD5VVi3ed0n9n_5t44chXHVrZLHcM/deleteMessage
2022-10-06 19:22:54,303 - apscheduler.scheduler - INFO - Scheduler started
2022-10-06 19:26:05,554 - apscheduler.scheduler - INFO - Scheduler started
2022-10-06 19:26:19,450 - telegram.ext.dispatcher - ERROR - No error handlers are registered, logging exception.
Traceback (most recent call last):
  File "/home/yusifmorley/Project/PycharmProject/TelegramBot/venv/lib/python3.10/site-packages/mysql/connector/connection_cext.py", line 535, in cmd_query
    self._cmysql.query(query,
_mysql_connector.MySQLInterfaceError: Duplicate entry '507467074' for key 'bans.PRIMARY'

During handling of the above exception, another exception occurred:

Traceback (most recent call last):
  File "/home/yusifmorley/Project/PycharmProject/TelegramBot/venv/lib/python3.10/site-packages/telegram/ext/dispatcher.py", line 555, in process_update
    handler.handle_update(update, self, check, context)
  File "/home/yusifmorley/Project/PycharmProject/TelegramBot/venv/lib/python3.10/site-packages/telegram/ext/handler.py", line 198, in handle_update
    return self.callback(update, context)
  File "/home/yusifmorley/Project/PycharmProject/TelegramBot/main2.py", line 101, in adminhanderex
    mysqlop.creatbanuser(mydb,update.effective_user.id,os)
  File "/home/yusifmorley/Project/PycharmProject/TelegramBot/mysqlop.py", line 108, in creatbanuser
    mycursor.execute("insert into bans (uid, banword) values({},'{}')".format(id,banword))
  File "/home/yusifmorley/Project/PycharmProject/TelegramBot/venv/lib/python3.10/site-packages/mysql/connector/cursor_cext.py", line 269, in execute
    result = self._cnx.cmd_query(stmt, raw=self._raw,
  File "/home/yusifmorley/Project/PycharmProject/TelegramBot/venv/lib/python3.10/site-packages/mysql/connector/connection_cext.py", line 540, in cmd_query
    raise errors.get_mysql_exception(exc.errno, msg=exc.msg,
mysql.connector.errors.IntegrityError: 1062 (23000): Duplicate entry '507467074' for key 'bans.PRIMARY'
2022-10-06 19:27:06,556 - apscheduler.scheduler - INFO - Scheduler started
2022-10-06 19:27:11,615 - telegram.vendor.ptb_urllib3.urllib3.connectionpool - WARNING - Retrying (Retry(total=2, connect=None, read=None, redirect=None)) after connection broken by 'ConnectTimeoutError(<telegram.vendor.ptb_urllib3.urllib3.connectionpool.HTTPSConnectionPool object at 0x7f1ed8b04850>, 'Connect timed out. (connect timeout=5.0)')': /bot5738858657:AAFJmjtD5VVi3ed0n9n_5t44chXHVrZLHcM/getMe
2022-10-06 19:27:28,557 - telegram.ext.dispatcher - ERROR - No error handlers are registered, logging exception.
Traceback (most recent call last):
  File "/home/yusifmorley/Project/PycharmProject/TelegramBot/venv/lib/python3.10/site-packages/mysql/connector/connection_cext.py", line 535, in cmd_query
    self._cmysql.query(query,
_mysql_connector.MySQLInterfaceError: Duplicate entry '507467074' for key 'bans.PRIMARY'

During handling of the above exception, another exception occurred:

Traceback (most recent call last):
  File "/home/yusifmorley/Project/PycharmProject/TelegramBot/venv/lib/python3.10/site-packages/telegram/ext/dispatcher.py", line 555, in process_update
    handler.handle_update(update, self, check, context)
  File "/home/yusifmorley/Project/PycharmProject/TelegramBot/venv/lib/python3.10/site-packages/telegram/ext/handler.py", line 198, in handle_update
    return self.callback(update, context)
  File "/home/yusifmorley/Project/PycharmProject/TelegramBot/main2.py", line 101, in adminhanderex
    mysqlop.creatbanuser(mydb,update.effective_user.id,os)
  File "/home/yusifmorley/Project/PycharmProject/TelegramBot/mysqlop.py", line 108, in creatbanuser
    mycursor.execute("insert into bans (uid, banword) values({},'{}')".format(id,banword))
  File "/home/yusifmorley/Project/PycharmProject/TelegramBot/venv/lib/python3.10/site-packages/mysql/connector/cursor_cext.py", line 269, in execute
    result = self._cnx.cmd_query(stmt, raw=self._raw,
  File "/home/yusifmorley/Project/PycharmProject/TelegramBot/venv/lib/python3.10/site-packages/mysql/connector/connection_cext.py", line 540, in cmd_query
    raise errors.get_mysql_exception(exc.errno, msg=exc.msg,
mysql.connector.errors.IntegrityError: 1062 (23000): Duplicate entry '507467074' for key 'bans.PRIMARY'
2022-10-06 19:27:50,816 - apscheduler.scheduler - INFO - Scheduler started
2022-10-06 19:29:24,901 - telegram.ext.dispatcher - ERROR - No error handlers are registered, logging exception.
Traceback (most recent call last):
  File "/home/yusifmorley/Project/PycharmProject/TelegramBot/venv/lib/python3.10/site-packages/telegram/ext/dispatcher.py", line 555, in process_update
    handler.handle_update(update, self, check, context)
  File "/home/yusifmorley/Project/PycharmProject/TelegramBot/venv/lib/python3.10/site-packages/telegram/ext/handler.py", line 198, in handle_update
    return self.callback(update, context)
  File "/home/yusifmorley/Project/PycharmProject/TelegramBot/main2.py", line 125, in adminhanderex
    mysqlop.getbanwords(mydb,update.effective_user.id)+os
  File "/home/yusifmorley/Project/PycharmProject/TelegramBot/mysqlop.py", line 114, in getbanwords
    return mycursor.fetchone[0]
TypeError: 'method' object is not subscriptable
2022-10-06 19:32:44,282 - apscheduler.scheduler - INFO - Scheduler started
2022-10-06 19:32:51,419 - root - INFO - 用户id :507467074 用户名 :morley dimu已被永久封禁，由于触发违禁词@-@-@-@@
2022-10-06 19:36:12,143 - apscheduler.scheduler - INFO - Scheduler started
